Workbook

Sheet Events 2026
AA1: Cheltuieli
A2: Data | B2: Tip Event | C2: Specific | D2: Locatie | E2: Descriere | F2: Nr. Ctr. | G2: Total | H2: Valuta | I2: Avans | J2: Valuta | K2: 0.01 | L2: TCH | M2: Profit | N2: Fond | O2: %fond | P2: DivPH | Q2: AlteDiv | R2: %DIV | S2: Phaser | T2: Calcul Artist | U2: Artist Real | V2: Restul | W2: Valuta | Y2: Detalii | AA2: Prezent | AB2: Pret | AC2: Tehnici | AD2: Pret | AE2: Drum | AF2: Pret | AG2: Lumini | AH2: Pret | AI2: DJ | AJ2: Pret | AK2: Extra | AL2: Pret
A3: Ianuarie
A4: Februarie
A5: Martie
A6: Aprilie
A7: Mai
A8: 30 | B8: Privat | C8: Nunta | D8: Plaja Noua | F8: 228 | G8: 3850 | H8: EUR | I8: 350 | J8: EUR | K8: =round(G8*1%,0) -> 39 | L8: =sum(AB8+AD8+AF8+AH8+AJ8+AL8) -> 440 | M8: =G8-K8-L8 -> 3371 | N8: =round(O8*M8+I8,0) -> 687 | O8: 0.1 | P8: =round(R8*(M8-N8),0) -> 268 | Q8: =round(R8*AD8,0) -> 24 | R8: 0.1 | S8: =round(M8-N8-P8-Q8,0) -> 2392 | T8: =S8/5 -> 478.4 | U8: =round(T8,-1) -> 480 | V8: =5*(T8-U8) -> -8 | AA8: Backline | AB8: 200 | AD8: 240
A9: Iunie
A10: 6 | B10: Privat | C10: Nunta | D10: Pallazo | F10: 219 | G10: 4450 | H10: EUR | I10: 450 | J10: EUR | K10: =round(G10*1%,0) -> 45 | L10: =sum(AB10+AD10+AF10+AH10+AJ10+AL10) -> 1040 | M10: =G10-K10-L10 -> 3365 | N10: =round(O10*M10+I10,0) -> 787 | O10: 0.1 | P10: =round(R10*(M10-N10),0) -> 258 | Q10: =round(R10*AD10,0) -> 24 | R10: 0.1 | S10: =round(M10-N10-P10-Q10,0) -> 2296 | T10: =S10/5 -> 459.2 | U10: =round(T10,-1) -> 460 | V10: =5*(T10-U10) -> -4 | AA10: Backline | AB10: 200 | AD10: 240 | AI10: Flavius | AJ10: 600
A11: Iulie
A12: 25 | B12: Privat | C12: Nunta | D12: Luxury Events Ballroom @ Cunta | F12: 237 | G12: 4050 | H12: EUR | I12: 400 | J12: EUR | K12: =round(G12*1%,0) -> 41 | L12: =sum(AB12+AD12+AF12+AH12+AJ12+AL12) -> 440 | M12: =G12-K12-L12 -> 3569 | N12: =round(O12*M12+I12,0) -> 757 | O12: 0.1 | P12: =round(R12*(M12-N12),0) -> 281 | Q12: =round(R12*AD12,0) -> 24 | R12: 0.1 | S12: =round(M12-N12-P12-Q12,0) -> 2507 | T12: =S12/5 -> 501.4 | U12: =round(T12,-1) -> 500 | V12: =5*(T12-U12) -> 7 | AA12: Backline | AB12: 200 | AD12: 240
A13: August
A14: 22 | B14: Privat | C14: Nunta | D14: Province | F14: 229 | G14: 4950 | H14: EUR | I14: 450 | J14: EUR | K14: =round(G14*1%,0) -> 50 | L14: =sum(AB14+AD14+AF14+AH14+AJ14+AL14) -> 1240 | M14: =G14-K14-L14 -> 3660 | N14: =round(O14*M14+I14,0) -> 816 | O14: 0.1 | P14: =round(R14*(M14-N14),0) -> 284 | Q14: =round(R14*AD14,0) -> 24 | R14: 0.1 | S14: =round(M14-N14-P14-Q14,0) -> 2536 | T14: =S14/5 -> 507.2 | U14: =round(T14,-1) -> 510 | V14: =5*(T14-U14) -> -14 | AA14: Sistem Full | AB14: 400 | AD14: 240 | AG14: Flavius | AH14: 600
A15: Septembrie
A16: 19 | B16: Privat | C16: Nunta | D16: Domeniul Lupas | F16: 234 | G16: 3950 | H16: EUR | I16: 350 | J16: EUR | K16: =round(G16*1%,0) -> 40 | L16: =sum(AB16+AD16+AF16+AH16+AJ16+AL16) -> 540 | M16: =G16-K16-L16 -> 3370 | N16: =round(O16*M16+I16,0) -> 687 | O16: 0.1 | P16: =round(R16*(M16-N16),0) -> 268 | Q16: =round(R16*AD16,0) -> 24 | R16: 0.1 | S16: =round(M16-N16-P16-Q16,0) -> 2391 | T16: =S16/5 -> 478.2 | U16: =round(T16,-1) -> 480 | V16: =5*(T16-U16) -> -9 | AA16: Backline | AB16: 200 | AD16: 240 | AF16: 100
A17: 26 | B17: Privat | C17: Nunta | D17: Chrystal Ballroom Venue | F17: 235 | G17: 3850 | H17: EUR | I17: 350 | J17: EUR | K17: =round(G17*1%,0) -> 39 | L17: =sum(AB17+AD17+AF17+AH17+AJ17+AL17) -> 440 | M17: =G17-K17-L17 -> 3371 | N17: =round(O17*M17+I17,0) -> 687 | O17: 0.1 | P17: =round(R17*(M17-N17),0) -> 268 | Q17: =round(R17*AD17,0) -> 24 | R17: 0.1 | S17: =round(M17-N17-P17-Q17,0) -> 2392 | T17: =S17/5 -> 478.4 | U17: =round(T17,-1) -> 480 | V17: =5*(T17-U17) -> -8 | AA17: Backline | AB17: 200 | AD17: 240
A18: Octombrie
A19: 10 | B19: Privat | C19: Nunta | D19: Sala noua @ Flonta | F19: 239 | G19: 4100 | H19: EUR | I19: 400 | J19: EUR | K19: =round(G19*1%,0) -> 41 | L19: =sum(AB19+AD19+AF19+AH19+AJ19+AL19) -> 440 | M19: =G19-K19-L19 -> 3619 | N19: =round(O19*M19+I19,0) -> 762 | O19: 0.1 | P19: =round(R19*(M19-N19),0) -> 286 | Q19: =round(R19*AD19,0) -> 24 | R19: 0.1 | S19: =round(M19-N19-P19-Q19,0) -> 2547 | T19: =S19/5 -> 509.4 | U19: =round(T19,-1) -> 510 | V19: =5*(T19-U19) -> -3 | AA19: Backline | AB19: 200 | AD19: 240
A20: Decembrie
A22: TEST | K22: =round(G22*1%,0) -> 0 | L22: =sum(AB22+AD22+AF22+AH22+AJ22+AL22) -> 0 | M22: =G22-K22-L22 -> 0 | N22: =round(O22*M22+I22,0) -> 0 | O22: 0.1 | P22: =round(R22*(M22-N22),0) -> 0 | Q22: =round(R22*AD22,0) -> 0 | R22: 0.1 | S22: =round(M22-N22-P22-Q22,0) -> 0 | T22: =S22/5 -> 0 | U22: =round(T22,-1) -> 0 | V22: =5*(T22-U22) -> 0

Sheet Evenimente 2025
AA1: Cheltuieli
A2: Data | B2: Tip Event | C2: Specific | D2: Locatie | E2: Descriere | F2: Nr. Ctr. | G2: Total | H2: Valuta | I2: Avans | J2: Valuta | K2: 0.01 | L2: TCH | M2: Profit | N2: Fond | O2: %fond | P2: DivPH | Q2: AlteDiv | R2: %DIV | S2: Phaser | T2: Calcul Artist | U2: Artist Real | V2: Restul | W2: Valuta | Y2: Detalii | AA2: Prezent | AB2: Pret | AC2: Tehnici | AD2: Pret | AE2: Drum | AF2: Pret | AG2: Lumini | AH2: Pret | AI2: DJ | AJ2: Pret | AK2: Extra | AL2: Pret
A3: Ianuarie
A4: 13 | B4: Public | C4: Concert Phaser | D4: Livigno @ Italia | E4: Snow Fest Italia | G4: 0 | H4: RON | I4: 0 | J4: RON | K4: =round(G4*1%,0) -> 0 | L4: =sum(AB4+AD4+AF4+AH4+AJ4+AL4) -> 0 | M4: =G4-K4-L4 -> 0 | N4: =round(O4*M4+I4,0) -> 0 | O4: 0 | P4: =round(R4*(M4-N4),0) -> 0 | Q4: =round(R4*AD4,0) -> 0 | R4: 0.1 | S4: =round(M4-N4-P4-Q4,0) -> 0 | T4: =S4/5 -> 0 | U4: =round(T4,-1) -> 0 | V4: =5*(T4-U4) -> 0 | W4: RON | AA4: Backline | AB4: 0
A5: 15 | B5: Public | C5: Concert Phaser | D5: Livigno @ Italia | E5: Snow Fest Italia | G5: 0 | H5: RON | I5: 0 | J5: RON | K5: =round(G5*1%,0) -> 0 | L5: =sum(AB5+AD5+AF5+AH5+AJ5+AL5) -> 0 | M5: =G5-K5-L5 -> 0 | N5: =round(O5*M5+I5,0) -> 0 | O5: 0 | P5: =round(R5*(M5-N5),0) -> 0 | Q5: =round(R5*AD5,0) -> 0 | R5: 0.1 | S5: =round(M5-N5-P5-Q5,0) -> 0 | T5: =S5/5 -> 0 | U5: =round(T5,-1) -> 0 | V5: =5*(T5-U5) -> 0 | W5: RON | AA5: Backline | AB5: 0
A6: 31 | B6: Public | C6: Concert Phaser | D6: Kai @ Timisoara | G6: 6000 | H6: RON | I6: 0 | J6: RON | K6: =round(G6*1%,0) -> 60 | L6: =sum(AB6+AD6+AF6+AH6+AJ6+AL6) -> 2000 | M6: =G6-K6-L6 -> 3940 | N6: =round(O6*M6+I6,0) -> -39 | O6: -0.01 | P6: =round(R6*(M6-N6),0) -> 398 | Q6: =round(R6*AD6,0) -> 100 | R6: 0.1 | S6: =round(M6-N6-P6-Q6,0) -> 3481 | T6: =S6/5 -> 696.2 | U6: =round(T6,-1) -> 700 | V6: =5*(T6-U6) -> -19 | W6: RON | AA6: Backline | AB6: 1000 | AD6: 1000
A7: Februarie
A8: Martie
A9: 26 | B9: Public | C9: Concert Phaser | D9: Les Deux Alps @ Franta | E9: Snow Fest Franta | G9: 600 | H9: EUR | I9: 0 | J9: EUR | K9: 0 | L9: =sum(AB9+AD9+AF9+AH9+AJ9+AL9) -> 0 | M9: =G9-K9-L9 -> 600 | N9: =round(O9*M9+I9,0) -> 0 | O9: 0 | P9: =round(R9*(M9-N9),0) -> 0 | Q9: =round(R9*AD9,0) -> 0 | R9: 0 | S9: =round(M9-N9-P9-Q9,0) -> 600 | T9: =S9/5 -> 120 | U9: =round(T9,-1) -> 120 | V9: =5*(T9-U9) -> 0 | W9: EUR | AA9: Backline | AB9: 0
A10: 31 | B10: Public | C10: Concert Phaser | D10: Val Thorens @ Franta | E10: Snow Fest Franta | G10: 800 | H10: EUR | I10: 0 | J10: EUR | K10: 0 | L10: =sum(AB10+AD10+AF10+AH10+AJ10+AL10) -> 0 | M10: =G10-K10-L10 -> 800 | N10: =round(O10*M10+I10,0) -> 0 | O10: 0 | P10: =round(R10*(M10-N10),0) -> 0 | Q10: =round(R10*AD10,0) -> 0 | R10: 0 | S10: =round(M10-N10-P10-Q10,0) -> 800 | T10: =S10/5 -> 160 | U10: =round(T10,-1) -> 160 | V10: =5*(T10-U10) -> 0 | W10: EUR | AA10: Backline | AB10: 0
A11: Aprilie
A12: 12 | B12: Privat | C12: Extra | D12: Plaja Noua | E12: Targ de nunti | G12: 0 | H12: RON | I12: 0 | J12: RON | K12: =round(G12*1%,0) -> 0 | L12: =sum(AB12+AD12+AF12+AH12+AJ12+AL12) -> 500 | M12: =G12-K12-L12 -> -500 | N12: =round(O12*M12+I12,0) -> 0 | O12: 0 | P12: =round(R12*(M12-N12),0) -> -50 | Q12: =round(R12*AD12,0) -> 50 | R12: 0.1 | S12: 0 | T12: 0 | U12: 0 | V12: =5*(T12-U12) -> 0 | W12: RON | AA12: Backline | AB12: 0 | AD12: 500
A13: 12 | B13: Public | C13: Scena Mare | D13: Timisoara | E13: Targul de Pasti | G13: 10000 | H13: RON | J13: RON | K13: =round(G13*1%,0) -> 100 | L13: =sum(AB13+AD13+AF13+AH13+AJ13+AL13) -> 2000 | M13: =G13-K13-L13 -> 7900 | N13: =round(O13*M13+I13,0) -> 1106 | O13: 0.14 | P13: =round(R13*(M13-N13),0) -> 679 | Q13: =round(R13*AD13,0) -> 100 | R13: 0.1 | S13: =round(M13-N13-P13-Q13,0) -> 6015 | T13: =S13/5 -> 1203 | U13: =round(T13,-1) -> 1200 | V13: =5*(T13-U13) -> 15 | AA13: Backline | AB13: 1000 | AD13: 1000
A14: Mai
A15: 2 | B15: Privat | C15: Nunta | D15: Domeniile Streiului | F15: 212 | G15: 24105 | H15: EUR | I15: 2237 | J15: RON | K15: =round(I15*1%,0) -> 22 | L15: =sum(AB15+AD15+AF15+AH15+AJ15+AL15) -> 7000 | M15: =G15-K15-L15 -> 17083 | N15: =round(O15*M15+I15,0) -> 4372 | O15: 0.125 | P15: =round(R15*(M15-N15),0) -> 0 | Q15: =round(R15*AD15,0) -> 0 | R15: 0 | S15: =round(M15-N15-P15-Q15,0) -> 12711 | T15: =S15/5 -> 2542.2 | U15: =round(T15,-1) -> 2540 | V15: =5*(T15-U15) -> 11 | W15: RON | AA15: Sistem de sunet | AB15: 2000 | AD15: 1500 | AF15: 1000 | AI15: Flavius | AJ15: 2500
A16: 11 | B16: Privat | C16: Nunta | D16: Province | F16: 224 | G16: 17740 | H16: RON | I16: 1740 | J16: RON | K16: =round(I16*1%,0) -> 17 | L16: =sum(AB16+AD16+AF16+AH16+AJ16+AL16) -> 2250 | M16: =G16-K16-L16 -> 15473 | N16: =round(O16*M16+I16,0) -> 2823 | O16: 0.07 | P16: =round(R16*(M16-N16),0) -> 0 | Q16: =round(R16*AD16,0) -> 0 | R16: 0 | S16: =round(M16-N16-P16-Q16,0) -> 12650 | T16: =S16/5 -> 2530 | U16: =round(T16,-1) -> 2530 | V16: =5*(T16-U16) -> 0 | W16: RON | AA16: Backline | AB16: 1000 | AD16: 1000 | AF16: 250
A17: 23 | B17: Privat | C17: Botez | D17: Villa Trevi | G17: 3800 | H17: EUR | I17: 0 | J17: EUR | K17: =round(I17*1%,0) -> 0 | L17: =sum(AB17+AD17+AF17+AH17+AJ17+AL17) -> 650 | M17: =G17-K17-L17 -> 3150 | N17: =round(O17*M17+I17,0) -> 347 | O17: 0.11 | P17: =round(R17*(M17-N17),0) -> 0 | Q17: =round(R17*AD17,0) -> 0 | R17: 0 | S17: =round(M17-N17-P17-Q17,0) -> 2803 | T17: =S17/5 -> 560.6 | U17: =round(T17,-1) -> 560 | V17: =5*(T17-U17) -> 3 | AA17: Backline | AB17: 400 | AD17: 200 | AF17: 50
A18: 24 | B18: Privat | C18: Nunta | D18: Ivy Events | F18: 217 | G18: 4700 | H18: EUR | I18: 500 | J18: EUR | K18: =round(G18*1%,0) -> 47 | L18: =sum(AB18+AD18+AF18+AH18+AJ18+AL18) -> 800 | M18: =G18-K18-L18 -> 3853 | N18: =round(O18*M18+I18,0) -> 1078 | O18: 0.15 | P18: =round(R18*(M18-N18),0) -> 278 | Q18: =round(R18*AD18,0) -> 20 | R18: 0.1 | S18: =round(M18-N18-P18-Q18,0) -> 2477 | T18: =S18/5 -> 495.4 | U18: =round(T18,-1) -> 500 | V18: =5*(T18-U18) -> -23 | W18: EUR | AA18: Sistem de sunet | AB18: 400 | AD18: 200 | AG18: Flavius | AH18: 200
A19: 30 | B19: Privat | C19: Nunta | D19: Flonta | F19: 227 | G19: 3150 | H19: EUR | I19: 0 | J19: EUR | K19: =round(I19*1%,0) -> 0 | L19: =sum(AB19+AD19+AF19+AH19+AJ19+AL19) -> 600 | M19: =G19-K19-L19 -> 2550 | N19: =round(O19*M19+I19,0) -> 26 | O19: 0.01 | P19: =round(R19*(M19-N19),0) -> 0 | Q19: =round(R19*AD19,0) -> 0 | R19: 0 | S19: =round(M19-N19-P19-Q19,0) -> 2524 | T19: =S19/5 -> 504.8 | U19: =round(T19,-1) -> 500 | V19: =5*(T19-U19) -> 24 | W19: EUR | AA19: Sistem de sunet | AB19: 400 | AD19: 200
A20: 31 | B20: Privat | C20: Nunta | D20: Timeea @ Resita | F20: 189 | G20: 4300 | H20: EUR | I20: 0 | J20: EUR | K20: =round(I20*1%,0) -> 0 | L20: =sum(AB20+AD20+AF20+AH20+AJ20+AL20) -> 1450 | M20: =G20-K20-L20 -> 2850 | N20: =round(O20*M20+I20,0) -> 342 | O20: 0.12 | P20: =round(R20*(M20-N20),0) -> 0 | Q20: =round(R20*AD20,0) -> 0 | R20: 0 | S20: =round(M20-N20-P20-Q20,0) -> 2508 | T20: =S20/5 -> 501.6 | U20: =round(T20,-1) -> 500 | V20: =5*(T20-U20) -> 8 | W20: EUR | AA20: Sistem de sunet | AB20: 550 | AD20: 300 | AF20: 100 | AG20: Flavius | AH20: 500
A21: Iunie
A22: 8 | B22: Public | C22: Concert Phaser | D22: Bastion @ Timisoara | G22: 10000 | H22: RON | I22: 0 | J22: RON | K22: =round(G22*1%,0) -> 100 | L22: =sum(AB22+AD22+AF22+AH22+AJ22+AL22) -> 5900 | M22: =G22-K22-L22 -> 4000 | N22: =round(O22*M22+I22,0) -> -40 | O22: -0.01 | P22: =round(R22*(M22-N22),0) -> 404 | Q22: =round(R22*AD22,0) -> 150 | R22: 0.1 | S22: =round(M22-N22-P22-Q22,0) -> 3486 | T22: =S22/5 -> 697.2 | U22: =round(T22,-1) -> 700 | V22: =5*(T22-U22) -> -14 | W22: RON | AA22: Sistem de sunet | AB22: 2000 | AD22: 1500 | AK22: Cvartet | AL22: 2400
A23: 14 | B23: Privat | C23: Nunta | D23: Riviere Ballroom | F23: 218 | G23: 18065 | H23: RON | I23: 1715 | J23: RON | K23: =round(I23*1%,0) -> 17 | L23: =sum(AB23+AD23+AF23+AH23+AJ23+AL23) -> 2500 | M23: =G23-K23-L23 -> 15548 | N23: =round(O23*M23+I23,0) -> 3037 | O23: 0.085 | P23: =round(R23*(M23-N23),0) -> 0 | Q23: =round(R23*AD23,0) -> 0 | R23: 0 | S23: =round(M23-N23-P23-Q23,0) -> 12511 | T23: =S23/5 -> 2502.2 | U23: =round(T23,-1) -> 2500 | V23: =5*(T23-U23) -> 11 | W23: RON | AA23: Backline | AB23: 1000 | AD23: 1500
A24: 17 | B24: Privat | C24: Corporate | D24: Sky Restaurant | G24: 14912 | H24: RON | I24: 4312 | J24: RON | K24: =round(G24*1%,0) -> 149 | L24: =sum(AB24+AD24+AF24+AH24+AJ24+AL24) -> 2000 | M24: =G24-K24-L24 -> 12763 | N24: =round(O24*M24+I24,0) -> 4312 | O24: 0 | P24: =round(R24*(M24-N24),0) -> 845 | Q24: =round(R24*AD24,0) -> 100 | R24: 0.1 | S24: =round(M24-N24-P24-Q24,0) -> 7506 | T24: =S24/5 -> 1501.2 | U24: =round(T24,-1) -> 1500 | V24: =5*(T24-U24) -> 6 | W24: RON | AA24: Backline | AB24: 1000 | AD24: 1000
A25: 21 | B25: Public | C25: Scena Mare | D25: Timisoara | G25: 10000 | H25: RON | I25: 0 | J25: RON | K25: =round(G25*1%,0) -> 100 | L25: =sum(AB25+AD25+AF25+AH25+AJ25+AL25) -> 2000 | M25: =G25-K25-L25 -> 7900 | N25: =round(O25*M25+I25,0) -> 1106 | O25: 0.14 | P25: =round(R25*(M25-N25),0) -> 679 | Q25: =round(R25*AD25,0) -> 100 | R25: 0.1 | S25: =round(M25-N25-P25-Q25,0) -> 6015 | T25: =S25/5 -> 1203 | U25: =round(T25,-1) -> 1200 | V25: =5*(T25-U25) -> 15 | W25: RON | AA25: Backline | AB25: 1000 | AD25: 1000
A26: 22 | B26: Public | C26: Scena Mare | D26: Muzeul Satului | E26: Flight Festival | G26: 6000 | H26: RON | I26: 0 | J26: RON | K26: =round(G26*1%,0) -> 60 | L26: =sum(AB26+AD26+AF26+AH26+AJ26+AL26) -> 2750 | M26: =G26-K26-L26 -> 3190 | N26: =round(O26*M26+I26,0) -> 191 | O26: 0.06 | P26: =round(R26*(M26-N26),0) -> 0 | Q26: =round(R26*AD26,0) -> 0 | R26: 0 | S26: =round(M26-N26-P26-Q26,0) -> 2999 | T26: =S26/5 -> 599.8 | U26: =round(T26,-1) -> 600 | V26: =5*(T26-U26) -> -1 | W26: RON | AA26: Backline | AB26: 1000 | AD26: 1750
A27: 23 | B27: Privat | C27: Corporate | D27: Corpul diplomatic @ Bucuresti | G27: 19349 | H27: RON | I27: 6719 | J27: RON | K27: =round(G27*1%,0) -> 193 | L27: =sum(AB27+AD27+AF27+AH27+AJ27+AL27) -> 4500 | M27: =G27-K27-L27 -> 14656 | N27: =round(O27*M27+I27,0) -> 563 | O27: -0.42 | P27: =round(R27*(M27-N27),0) -> 1409 | Q27: =round(R27*AD27,0) -> 200 | R27: 0.1 | S27: =round(M27-N27-P27-Q27,0) -> 12484 | T27: =S27/5 -> 2496.8 | U27: =round(T27,-1) -> 2500 | V27: =5*(T27-U27) -> -16 | W27: RON | AA27: Backline | AB27: 1000 | AD27: 2000 | AF27: 1500
A28: Iulie
A29: 5 | B29: Privat | C29: Corporate | D29: Hotel Timisoara | E29: LifeCare | G29: 11392 | H29: RON | I29: 1257 | J29: RON | K29: =round(G29*1%,0) -> 114 | L29: =sum(AB29+AD29+AF29+AH29+AJ29+AL29) -> 2000 | M29: =G29-K29-L29 -> 9278 | N29: =round(O29*M29+I29,0) -> 2231 | O29: 0.105 | P29: =round(R29*(M29-N29),0) -> 705 | Q29: =round(R29*AD29,0) -> 100 | R29: 0.1 | S29: =round(M29-N29-P29-Q29,0) -> 6242 | T29: =S29/5 -> 1248.4 | U29: =round(T29,-1) -> 1250 | V29: =5*(T29-U29) -> -8 | W29: RON | AA29: Backline | AB29: 1000 | AD29: 1000
A30: 6 | B30: Privat | C30: Nunta | D30: Province | F30: 226 | G30: 4350 | H30: EUR | I30: 0 | J30: EUR | K30: =round(I30*1%,0) -> 0 | L30: =sum(AB30+AD30+AF30+AH30+AJ30+AL30) -> 1250 | M30: =G30-K30-L30 -> 3100 | N30: =round(O30*M30+I30,0) -> 589 | O30: 0.19 | P30: =round(R30*(M30-N30),0) -> 0 | Q30: =round(R30*AD30,0) -> 0 | R30: 0 | S30: =round(M30-N30-P30-Q30,0) -> 2511 | T30: =S30/5 -> 502.2 | U30: =round(T30,-1) -> 500 | V30: =5*(T30-U30) -> 11 | W30: EUR | AA30: Sistem de sunet | AB30: 400 | AD30: 200 | AF30: 50 | AG30: Flavius | AH30: 500 | AK30: Podium | AL30: 100
A31: August
A32: 16 | B32: Privat | C32: Nunta | D32: Convention Center @ Timisoara | F32: 207 | G32: 27771 | H32: RON | I32: 2585 | J32: RON | K32: =round(G32*1%,0) -> 278 | L32: =sum(AB32+AD32+AF32+AH32+AJ32+AL32) -> 8750 | M32: =G32-K32-L32 -> 18743 | N32: =round(O32*M32+I32,0) -> 4647 | O32: 0.11 | P32: =round(R32*(M32-N32),0) -> 1410 | Q32: =round(R32*AD32,0) -> 200 | R32: 0.1 | S32: =round(M32-N32-P32-Q32,0) -> 12486 | T32: =S32/5 -> 2497.2 | U32: =round(T32,-1) -> 2500 | V32: =5*(T32-U32) -> -14 | W32: RON | AA32: Sistem de sunet | AB32: 2000 | AD32: 2000 | AG32: Flavius | AH32: 2075 | AI32: Flavius | AJ32: 2075 | AK32: Podium | AL32: 600
A33: 30 | B33: Privat | C33: Nunta | D33: Hotel Tresor @ Timisoara | F33: 225 | G33: 3350 | H33: EUR | I33: 350 | J33: EUR | K33: =round(G33*1%,0) -> 34 | L33: =sum(AB33+AD33+AF33+AH33+AJ33+AL33) -> 400 | M33: =G33-K33-L33 -> 2916 | N33: =round(O33*M33+I33,0) -> 408 | O33: 0.02 | P33: =round(R33*(M33-N33),0) -> 0 | Q33: =round(R33*AD33,0) -> 0 | R33: 0 | S33: =round(M33-N33-P33-Q33,0) -> 2508 | T33: =S33/5 -> 501.6 | U33: =round(T33,-1) -> 500 | V33: =5*(T33-U33) -> 8 | W33: EUR | AA33: Backline | AB33: 200 | AD33: 200
A34: Septembrie
A35: 6 | B35: Privat | C35: Nunta | D35: Heaven Outdoor | F35: 237 | G35: 16250 | H35: RON | I35: 1750 | J35: RON | K35: =round(I35*1%,0) -> 18 | L35: =sum(AB35+AD35+AF35+AH35+AJ35+AL35) -> 4950 | M35: =G35-K35-L35 -> 11282 | N35: =round(O35*M35+I35,0) -> 3781 | O35: 0.18 | P35: =round(R35*(M35-N35),0) -> 0 | Q35: =round(R35*AD35,0) -> 0 | R35: 0 | S35: =round(M35-N35-P35-Q35,0) -> 7501 | T35: =S35/5 -> 1500.2 | U35: =round(T35,-1) -> 1500 | V35: =5*(T35-U35) -> 1 | W35: RON | AA35: Backline | AB35: 2250 | AD35: 2000 | AK35: Podium | AL35: 700
A36: 6 | B36: Public | C36: Scena Mare | D36: Giarmata | E36: Zilele Orasului | G36: 10000 | H36: RON | I36: 0 | J36: RON | K36: =round(G36*1%,0) -> 100 | L36: =sum(AB36+AD36+AF36+AH36+AJ36+AL36) -> 2500 | M36: =G36-K36-L36 -> 7400 | N36: =round(O36*M36+I36,0) -> 370 | O36: 0.05 | P36: =round(R36*(M36-N36),0) -> 703 | Q36: =round(R36*AD36,0) -> 100 | R36: 0.1 | S36: =round(M36-N36-P36-Q36,0) -> 6227 | T36: =S36/5 -> 1245.4 | U36: =round(T36,-1) -> 1250 | V36: =5*(T36-U36) -> -23 | W36: RON | AA36: Backline | AB36: 1000 | AD36: 1000 | AK36: in-ear + tobe | AL36: 500
A37: 13 | B37: Privat | C37: Nunta | D37: Continental | F37: 194 | G37: 3450 | H37: EUR | I37: 300 | J37: EUR | K37: =round(I37*1%,0) -> 3 | L37: =sum(AB37+AD37+AF37+AH37+AJ37+AL37) -> 400 | M37: =G37-K37-L37 -> 3047 | N37: =round(O37*M37+I37,0) -> 544 | O37: 0.08 | P37: =round(R37*(M37-N37),0) -> 0 | Q37: =round(R37*AD37,0) -> 0 | R37: 0 | S37: =round(M37-N37-P37-Q37,0) -> 2503 | T37: =S37/5 -> 500.6 | U37: =round(T37,-1) -> 500 | V37: =5*(T37-U37) -> 3 | W37: EUR | AA37: Backline | AB37: 200 | AD37: 200
A38: 20 | B38: Privat | C38: Nunta | D38: Palazzo Events | F38: 211 | G38: 19240 | H38: EUR | I38: 1740 | J38: RON | K38: =round(I38*1%,0) -> 17 | L38: =sum(AB38+AD38+AF38+AH38+AJ38+AL38) -> 2000 | M38: =G38-K38-L38 -> 17223 | N38: =round(O38*M38+I38,0) -> 4737 | O38: 0.174 | P38: =round(R38*(M38-N38),0) -> 0 | Q38: =round(R38*AD38,0) -> 0 | R38: 0 | S38: =round(M38-N38-P38-Q38,0) -> 12486 | T38: =S38/5 -> 2497.2 | U38: =round(T38,-1) -> 2500 | V38: =5*(T38-U38) -> -14 | W38: RON | AA38: Backline | AB38: 1000 | AD38: 1000
A39: 27 | B39: Privat | C39: Nunta | D39: Province | F39: 209 | G39: 5500 | H39: EUR | I39: 500 | J39: EUR | K39: =round(I39*1%,0) -> 5 | L39: =sum(AB39+AD39+AF39+AH39+AJ39+AL39) -> 1850 | M39: =G39-K39-L39 -> 3645 | N39: =round(O39*M39+I39,0) -> 1229 | O39: 0.2 | P39: =round(R39*(M39-N39),0) -> 0 | Q39: =round(R39*AD39,0) -> 0 | R39: 0 | S39: =round(M39-N39-P39-Q39,0) -> 2416 | T39: =S39/5 -> 483.2 | U39: =round(T39,-1) -> 480 | V39: =5*(T39-U39) -> 16 | W39: EUR | AA39: Sistem de sunet | AB39: 400 | AD39: 400 | AF39: 50 | AG39: Flavius | AH39: 400 | AI39: Flavius | AJ39: 500 | AK39: Podium | AL39: 100
A40: Octombrie
...

Sheet Onorariu Artist 2025
F1: Onorariu Artist
A2: Data | B2: Tip Event | C2: Specific | D2: Locatie | E2: Descriere | F2: POSIBIL | G2: REAL | H2: Valuta | I2: Carina | J2: Arni | K2: Radu | L2: Sebi | M2: Luci
A3: Ianuarie
A4: 13 | B4: Public | C4: Concert Phaser | D4: Livigno @ Italia | E4: Snow Fest Italia | F4: 0 | G4: 0 | H4: RON | I4: 0 | J4: 0 | K4: 0 | L4: 0 | M4: 0
A5: 15 | B5: Public | C5: Concert Phaser | D5: Livigno @ Italia | E5: Snow Fest Italia | F5: 0 | G5: 0 | H5: RON | I5: 0 | J5: 0 | K5: 0 | L5: 0 | M5: 0
A6: 31 | B6: Public | C6: Concert Phaser | D6: Kai @ Timisoara | F6: 530 | G6: 700 | H6: RON | I6: 700 | J6: 700 | K6: 700 | L6: 700 | M6: 700
A7: Februarie
A8: Martie
A9: 26 | B9: Public | C9: Concert Phaser | D9: Les Deux Alps @ Franta | E9: Snow Fest Franta | F9: 200 | G9: 200 | H9: EUR | I9: 100 | J9: 100 | K9: 100 | L9: 200 | M9: 100
A10: 31 | B10: Public | C10: Concert Phaser | D10: Val Thorens @ Franta | E10: Snow Fest Franta | F10: 200 | G10: 200 | H10: EUR | I10: 100 | J10: 200 | K10: 100 | L10: 200 | M10: 100
A11: Aprilie
A12: 12 | B12: Public | C12: Extra | D12: Plaja Noua | E12: Targ de nunti | F12: 0 | G12: 0 | H12: RON | I12: 0 | J12: 0 | K12: 0 | L12: 0 | M12: 0
A13: 12 | B13: Public | C13: Scena Mare | D13: Timisoara | E13: Targul de Pasti | F13: 1400 | G13: 1200 | H13: RON | I13: 1200 | J13: 1200 | K13: 1200 | L13: 1200 | M13: 1200
A14: Mai
A15: 2 | B15: Privat | C15: Nunta | D15: Domeniile Streiului | F15: 2930 | G15: 2500 | H15: RON | I15: 2500 | J15: 2500 | K15: 2500 | L15: 2500 | M15: 2500
A16: 11 | B16: Privat | C16: Nunta | D16: Province | F16: 2710 | G16: 2500 | H16: RON | I16: 2500 | J16: 2500 | K16: 2500 | L16: 2500 | M16: 2500
A17: 23 | B17: Privat | C17: Botez | D17: Villa Trevi | F17: 620 | G17: 550 | H17: EUR | I17: 550 | J17: 550 | K17: 550 | L17: 550 | M17: 550
A18: 24 | B18: Privat | C18: Nunta | D18: Ivy Events | F18: 610 | G18: 500 | H18: EUR | I18: 500 | J18: 500 | K18: 500 | L18: 500 | M18: 500
A19: 30 | B19: Privat | C19: Nunta | D19: Flonta LakeSide | F19: 500 | G19: 500 | H19: EUR | I19: 500 | J19: 500 | K19: 500 | L19: 500 | M19: 500
A20: 31 | B20: Privat | C20: Nunta | D20: Timeea @ Resita | F20: 590 | G20: 500 | H20: EUR | I20: 500 | J20: 500 | K20: 500 | L20: 500 | M20: 500
A21: Iunie
A22: 8 | B22: Public | C22: Concert Phaser | D22: Bastion | F22: 690 | G22: 700 | H22: RON | I22: 700 | J22: 700 | K22: 700 | L22: 700 | M22: 700
A23: 14 | B23: Privat | C23: Nunta | D23: Riviere Ballroom | F23: 2770 | G23: 2500 | H23: RON | I23: 2500 | J23: 2500 | K23: 2500 | L23: 2500 | M23: 2500
A24: 17 | B24: Privat | C24: Corporate | D24: Sky Restaurant | F24: 1500 | G24: 1500 | H24: RON | I24: 1500 | J24: 1500 | K24: 1500 | L24: 1500 | M24: 1500
A25: 21 | B25: Public | C25: Scena Mare | D25: Timisoara | F25: 1400 | G25: 1200 | H25: RON | I25: 1200 | J25: 1200 | K25: 1200 | L25: 1200 | M25: 1200
A26: 22 | B26: Public | C26: Scena Mare | D26: Muzeul Satului | E26: Flight Festival | F26: 640 | G26: 600 | H26: RON | I26: 600 | J26: 600 | K26: 600 | L26: 600 | M26: 600
A27: 23 | B27: Privat | C27: Corporate | D27: Corpul diplomatic @ Bucuresti | F27: 2526 | G27: 2500 | H27: RON | I27: 2500 | J27: 2500 | K27: 2500 | L27: 2500 | M27: 2500
A28: Iulie
A29: 5 | B29: Privat | C29: Corporate | D29: Hotel Timisoara | F29: 1420 | G29: 1250 | H29: RON | I29: 1250 | J29: 1250 | K29: 1250 | L29: 1250 | M29: 1250
A30: 6 | B30: Privat | C30: Nunta | D30: Province | F30: 610 | G30: 500 | H30: EUR | I30: 500 | J30: 500 | K30: 500 | L30: 500 | M30: 500
A31: August
A32: 16 | B32: Privat | C32: Nunta | D32: Convention Center @ Timisoara | F32: 2870 | G32: 2500 | H32: RON | I32: 2500 | J32: 2500 | K32: 2500 | L32: 2500 | M32: 2500
A33: 30 | B33: Privat | C33: Nunta | D33: Hotel Tresor @ Timisoara | F33: 570 | G33: 500 | H33: EUR | I33: 500 | J33: 500 | K33: 500 | L33: 500 | M33: 500
A34: Septembrie
A35: 6 | B35: Privat | C35: Nunta | D35: Heaven Outdoor | F35: 1910 | G35: 1500 | H35: RON | I35: 1500 | J35: 1500 | K35: 1500 | L35: 1500 | M35: 1500
A36: 6 | B36: Public | C36: Scena Mare | D36: Giarmata | E36: Zilele Giarmata | F36: 1310 | G36: 1250 | H36: RON | I36: 1250 | J36: 1250 | K36: 1250 | L36: 1250 | M36: 1250
A37: 13 | B37: Privat | C37: Nunta | D37: Continental | F37: 550 | G37: 500 | H37: EUR | I37: 500 | J37: 500 | K37: 500 | L37: 500 | M37: 500
A38: 20 | B38: Privat | C38: Nunta | D38: Palazzo Events | F38: 3100 | G38: 2500 | H38: RON | I38: 2500 | J38: 2500 | K38: 2500 | L38: 2500 | M38: 2500
A39: 27 | B39: Privat | C39: Nunta | D39: Province | F39: 650 | G39: 500 | H39: EUR | I39: 500 | J39: 500 | K39: 500 | L39: 500 | M39: 500
A40: Octombrie
...

Sheet Situatie 2025
A1: Venituri RON | B1: =SUMIF('Tranzactii 2025'!H:H,'Tranzactii 2025'!H4,'Tranzactii 2025'!G:G) -> 395227.4 | E1: Total Events | F1: =COUNT('Evenimente 2025'!A:A) -> 37 | L1: Eur | M1: 5
A2: Venituri EUR | B2: =sumif('Tranzactii 2025'!H:H,'Tranzactii 2025'!H95,'Tranzactii 2025'!G:G) -> 29750
A3: Cheltuieli RON | B3: =SUMIF('Tranzactii 2025'!C:C,'Tranzactii 2025'!C4,'Tranzactii 2025'!B:B) -> 386524.11 | E3: Public | F3: =countif('Evenimente 2025'!B:B,E3) -> 14
A4: Cheltuieli EUR | B4: =sumif('Tranzactii 2025'!C:C,'Tranzactii 2025'!C98,'Tranzactii 2025'!B:B) -> 29750 | E4: Concert Phaser | F4: =COUNTIF('Evenimente 2025'!C:C,E4) -> 7
A5: Retrageri | B5: =sum('Tranzactii 2025'!L:L) -> 244150 | C5: ron | E5: Scena mare | F5: =COUNTIF('Evenimente 2025'!C:C,E5) -> 7
A6: Depuneri | B6: =sum('Tranzactii 2025'!N:N) -> 32400 | C6: ron
A9: Recuperari | B9: ='DatoriiRecuperari 2025'!A14 -> 0 | E9: Privat | F9: =COUNTIF('Evenimente 2025'!B:B,E9) -> 23
A10: Datorii | B10: ='DatoriiRecuperari 2025'!A2 -> 2400 | E10: Nunta | F10: =COUNTIF('Evenimente 2025'!C:C,E10) -> 16
E11: Corporate | F11: =countif('Evenimente 2025'!C:C,E11) -> 5
A12: Balanta RON | B12: =B1-B3 -> 8703.29 | E12: Aniversare | F12: =COUNTIF('Evenimente 2025'!C:C,E12) -> 0
A13: Balanta EUR | B13: =B2-B4 -> 0 | C13: =B13*M1 -> 0
A14: Balanta | B14: =B12+C13 -> 8703.29 | C14: ron
A15: Total w.datorii&recuperari | B15: =B14-B10+B9 -> 6303.29 | C15: ron | E15: Extra | F15: =COUNTIF('Evenimente 2025'!C:C,E15) -> 1
A19: Onorariu Real 2025 RON | B19: =SUMIF('Onorariu Artist 2025'!H:H,'Onorariu Artist 2025'!H5,'Onorariu Artist 2025'!G:G) -> 28150
A20: Onorariu Real 2025 EUR | B20: =sumif('Onorariu Artist 2025'!H:H,'Onorariu Artist 2025'!H10,'Onorariu Artist 2025'!G:G) -> 5450
A21: Total Onorariu Real 2024 | B21: =round(B20+B19/M1,0) -> 11080 | C21: euro | E21: Comision Retrageri | F21: =SUMIF('Tranzactii 2025'!D:D,"Comision Retrageri",'Tranzactii 2025'!B:B) -> 593.35
E22: Comision Operatiune | F22: =SUMIF('Tranzactii 2025'!D:D,"Comision Operatiune",'Tranzactii 2025'!B:B) -> 114.02
A23: Total Onorariu Posibil 2025 RON | B23: =sumif('Onorariu Artist 2025'!H:H,'Onorariu Artist 2025'!H4,'Onorariu Artist 2025'!F:F) -> 30956 | E23: Salariu | F23: =SUMIF('Tranzactii 2025'!D:D,"Salariu",'Tranzactii 2025'!B:B) -> 21139
A24: Total Onorariu Posibil 2025 EUR | B24: =sumif('Onorariu Artist 2025'!H:H,'Onorariu Artist 2025'!H10,'Onorariu Artist 2025'!F:F) -> 6150 | E24: TVA | F24: =SUMIF('Tranzactii 2025'!D:D,"TVA",'Tranzactii 2025'!B:B) -> 291
A25: Total Onorariu Posibil 2025 | B25: =round(B24+B23/M1,0) -> 12341 | C25: euro | E25: ING Card | F25: =SUMIF('Tranzactii 2025'!D:D,"ING Card",'Tranzactii 2025'!B:B) -> 400
E26: Drive | F26: =SUMIF('Tranzactii 2025'!D:D,"Drive",'Tranzactii 2025'!B:B) -> 838.94
A29: Momentan
A30: In banca
A31: Cash

Sheet Tranzactii 2025
B1: Cheltuieli | G1: Venituri | L1: Retrageri | N1: Depuneri
A2: Data | B2: Suma | C2: Valuta | D2: Categorie | E2: Descriere | F2: Mod | G2: Suma | H2: Valuta | I2: Categorie | J2: Descriere | K2: Mod | L2: Suma | M2: Descriere | N2: Suma | O2: Descriere
A3: 45660 | B3: 71.01 | C3: Ron | D3: Drive | F3: Banca
A4: 45663 | B4: 2500 | C4: Ron | D4: Arni | E4: suceava | F4: Cash | G4: 21140.4 | H4: Ron | I4: Altele | J4: Sold initial 2025 | L4: 5000
B5: 2500 | C5: Ron | D5: Carina | E5: suceava | F5: Cash | L5: 4000
B6: 16 | C6: Ron | D6: Comision Retrageri | F6: Banca
A7: 45665 | B7: 200 | C7: Ron | D7: Radu | E7: recuperare cantare concert fitt | F7: Cash | G7: 22138 | H7: Ron | I7: Event | J7: ranking coach | K7: Banca | L7: 3000
B8: 9500 | C8: Ron | D8: Sebi | E8: Cantari dec 2024 | F8: Cash | L8: 5000
B9: 40 | C9: Ron | D9: Comision Retrageri | F9: Banca | L9: 2000
A11: 45666 | B11: 20 | C11: Ron | D11: Comision Retrageri | F11: Banca | G11: 15668 | H11: Ron | I11: Event | J11: rotary | K11: Banca | L11: 5000
B12: 16 | C12: Ron | D12: Comision Retrageri | F12: Banca | L12: 4000
B13: 12 | C13: Ron | D13: Comision Retrageri | F13: Banca | L13: 3000
B14: 20 | C14: Ron | D14: Comision Retrageri | F14: Banca | L14: 5000
B15: 8 | C15: Ron | D15: Comision Retrageri | F15: Banca | L15: 2000
B16: 1250 | C16: Ron | D16: Prezent | F16: Banca
B17: 11840 | C17: Ron | D17: Lumini | E17: Flavius | F17: Cash
B18: 0.45 | C18: Ron | D18: Comision Operatiune | F18: Banca
A19: 45668 | B19: 20 | C19: Ron | D19: Comision Retrageri | F19: Banca | L19: 5000
B20: 16 | C20: Ron | D20: Comision Retrageri | F20: Banca | L20: 4000
A21: 45677 | B21: 7.6 | C21: Ron | D21: Comision Retrageri | F21: Banca | L21: 1900
A22: 45679 | B22: 3200 | C22: Ron | D22: Protocol | E22: livigno | F22: Cash | G22: 9950 | H22: Ron | I22: Event | J22: fitt 2024 | K22: Banca
B23: 700 | C23: Ron | D23: Radu | E23: kai | F23: Cash
B24: 700 | C24: Ron | D24: Radu | E24: soho | F24: Cash
B25: 2000 | C25: Ron | D25: Radu | E25: province | F25: Cash
B26: 2000 | C26: Ron | D26: Radu | E26: rotary | F26: Cash
B27: 2500 | C27: Ron | D27: Radu | E27: tg jiu | F27: Cash
B28: 2500 | C28: Ron | D28: Arni | E28: revelion | F28: Cash
B29: 1000 | C29: Ron | D29: Arni | E29: parte din tg jiu | F29: Cash
A30: 45684 | B30: 4011 | C30: Ron | D30: Salariu | F30: Banca | L30: 4000
B31: 0.51 | C31: Ron | D31: Comision Operatiune | F31: Banca
B32: 231 | C32: Ron | D32: Salariu | F32: Banca
B33: 0.51 | C33: Ron | D33: Comision Operatiune | F33: Banca
B34: 13 | C34: Ron | D34: TVA | F34: Banca
B35: 0.51 | C35: Ron | D35: Comision Operatiune | F35: Banca
B36: 16 | C36: Ron | D36: Comision Retrageri | F36: Banca
A37: 45686 | B37: 12 | C37: Ron | D37: Comision Retrageri | F37: Banca | L37: 3000
A38: 45687 | B38: 4200 | C38: Ron | D38: Contabila | F38: Banca
A39: 45688 | B39: 40 | C39: Ron | D39: ING Card | F39: Banca
B40: 500 | C40: Ron | D40: Tehnici | F40: Cash
B41: 500 | C41: Ron | D41: Tehnici | F41: Cash
...

Sheet DatoriiRecuperari 2025
A1: TOTAL DATORII | C1: Datorie Prezent | G1: Datorii persoane | H1: Carina Social 2025 | K1: Alte datorii | N1: Recuperari
A2: =A5+A8+A11 -> 2400 | H2: Arni Tehnic | I2: 2400
A4: Total Prezent
A5: =sum(E:E) -> 0
A7: Total Pesoane
A8: =sum(I:I) -> 2400
A10: Total alte datorii
A11: =sum(L:L) -> 0
A13: TOTAL RECUPERARI
A14: =sum(P:P) -> 0

Sheet Situatie 2024
A1: Venituri RON | B1: =SUMIF('Tranzactii 2024'!H:H,'Tranzactii 2024'!H3,'Tranzactii 2024'!G:G) -> 395162.23 | E1: Total Events | F1: =COUNT('Evenimente 2024'!A:A) -> 48 | L1: Eur | M1: 4.9
A2: Venituri EUR | B2: =sumif('Tranzactii 2024'!H:H,'Tranzactii 2024'!H24,'Tranzactii 2024'!G:G) -> 43940
A3: Cheltuieli RON | B3: =SUMIF('Tranzactii 2024'!C:C,'Tranzactii 2024'!C3,'Tranzactii 2024'!B:B) -> 374021.83 | E3: Public | F3: =countif('Evenimente 2024'!B:B,E3) -> 23
A4: Cheltuieli EUR | B4: =sumif('Tranzactii 2024'!C:C,'Tranzactii 2024'!C24,'Tranzactii 2024'!B:B) -> 43940 | E4: Concert Phaser | F4: =COUNTIF('Evenimente 2024'!C:C,E4) -> 12
A5: Retrageri | B5: =sum('Tranzactii 2024'!L:L) -> 233490 | C5: ron | E5: Scena mare | F5: =COUNTIF('Evenimente 2024'!C:C,E5) -> 8
A6: Depuneri | B6: =sum('Tranzactii 2023'!N:N) -> 4750 | C6: ron
A9: Recuperari | B9: ='DatoriiRecuperari 2024'!A14 -> 0 | E9: Privat | F9: =COUNTIF('Evenimente 2024'!B:B,E9) -> 25
A10: Datorii | B10: ='DatoriiRecuperari 2024'!A2 -> 0 | E10: Nunta | F10: =COUNTIF('Evenimente 2024'!C:C,E10) -> 17
E11: Corporate | F11: =countif('Evenimente 2024'!C:C,E11) -> 7
A12: Balanta RON | B12: =B1-B3 -> 21140.4 | E12: Aniversare | F12: =COUNTIF('Evenimente 2024'!C:C,E12) -> 0
A13: Balanta EUR | B13: =B2-B4 -> 0 | C13: =B13*M1 -> 0
A14: Balanta | B14: =B12+C13 -> 21140.4 | C14: ron
A15: Total w.datorii&recuperari | B15: =B14-B10+B9 -> 21140.4 | C15: ron | E15: Extra | F15: =COUNTIF('Evenimente 2024'!C:C,E15) -> 3
A19: Onorariu Real 2024 RON | B19: =SUMIF('Onorariu Artist 2024'!H:H,'Onorariu Artist 2024'!H5,'Onorariu Artist 2024'!G:G) -> 37400
A20: Onorariu Real 2024 EUR | B20: =sumif('Onorariu Artist 2024'!H:H,'Onorariu Artist 2024'!H4,'Onorariu Artist 2024'!G:G) -> 6850
A21: Total Onorariu Real 2024 | B21: =round(B20+B19/M1,0) -> 14483 | C21: euro | E21: Comision Retrageri | F21: =SUMIF('Tranzactii 2024'!D:D,"Comision Retrageri",'Tranzactii 2024'!B:B) -> 749.25
E22: Comision Operatiune | F22: =SUMIF('Tranzactii 2024'!D:D,"Comision Operatiune",'Tranzactii 2024'!B:B) -> 15.33
A23: Total Onorariu Posibil 2024 RON | B23: =sumif('Onorariu Artist 2024'!H:H,'Onorariu Artist 2024'!H5,'Onorariu Artist 2024'!F:F) -> 41070 | E23: Salariu | F23: =SUMIF('Tranzactii 2024'!D:D,"Salariu",'Tranzactii 2024'!B:B) -> 16644
A24: Total Onorariu Posibil 2024 EUR | B24: =sumif('Onorariu Artist 2024'!H:H,'Onorariu Artist 2024'!H4,'Onorariu Artist 2024'!F:F) -> 7300 | E24: TVA | F24: =SUMIF('Tranzactii 2024'!D:D,"TVA",'Tranzactii 2024'!B:B) -> 669
A25: Total Onorariu Posibil 2024 | B25: =round(B24+B23/M1,0) -> 15682 | C25: euro | E25: ING Card | F25: =SUMIF('Tranzactii 2024'!D:D,"ING Card",'Tranzactii 2024'!B:B) -> 415
E26: Drive | F26: =SUMIF('Tranzactii 2024'!D:D,"Drive",'Tranzactii 2024'!B:B) -> 2157.05
A29: Momentan
A30: In banca | B30: =#REF!+B31+B32 -> #REF!
A31: Cash

Sheet Evenimente 2024
AA1: Cheltuieli
A2: Data | B2: Tip Event | C2: Specific | D2: Locatie | E2: Descriere | F2: Nr. Ctr. | G2: Total | H2: Valuta | I2: Avans | J2: Valuta | K2: 0.01 | L2: TCH | M2: Profit | N2: Fond | O2: %fond | P2: DivPH | Q2: AlteDiv | R2: %DIV | S2: Phaser | T2: Calcul Artist | U2: Artist Real | V2: Restul | W2: Valuta | Y2: Detalii | AA2: Prezent | AB2: Pret | AC2: Tehnici | AD2: Pret | AE2: Drum | AF2: Pret | AG2: Lumini | AH2: Pret | AI2: DJ | AJ2: Pret | AK2: Extra | AL2: Pret
A3: Ianuarie
A4: 27 | B4: Privat | C4: Nunta | D4: Flonta (Lakeside) | F4: 192 | G4: 3300 | H4: EUR | I4: 300 | J4: EUR | K4: =round(I4*1%,0) -> 3 | L4: =sum(AB4+AD4+AF4+AH4+AJ4+AL4) -> 350 | M4: =G4-K4-L4 -> 2947 | N4: =round(O4*M4+I4,0) -> 447 | O4: 0.05 | P4: =round(R4*(M4-N4),0) -> 0 | Q4: =round(R4*AD4,0) -> 0 | R4: 0 | S4: =round(M4-N4-P4-Q4,0) -> 2500 | T4: =S4/5 -> 500 | U4: =round(T4,-1) -> 500 | V4: =5*(T4-U4) -> 0 | W4: RON | AA4: Sunet Full | AB4: 350
A5: 29 | B5: Public | C5: Extra | D5: Radio Resita | E5: Concert in Studio Radio Resita | G5: 0 | H5: RON | I5: 0 | J5: RON | K5: =round(G5*1%,0) -> 0 | L5: =sum(AB5+AD5+AF5+AH5+AJ5+AL5) -> 250 | M5: =G5-K5-L5 -> -250 | N5: =round(O5*M5+I5,0) -> 0 | O5: 0 | P5: =round(R5*(M5-N5),0) -> 0 | Q5: =round(R5*AD5,0) -> 0 | R5: 0 | S5: =round(M5-N5-P5-Q5,0) -> -250 | T5: 0 | U5: 0 | V5: =5*(T5-U5) -> 0 | W5: RON | AA5: Backline | AB5: 0 | AC5: Misu Aurel | AD5: 250
A6: Februarie
A7: 2 | B7: Public | C7: Concert Phaser | D7: Kai @ Timisoara | G7: 6000 | H7: RON | I7: 0 | J7: RON | K7: =round(G7*1%,0) -> 60 | L7: =sum(AB7+AD7+AF7+AH7+AJ7+AL7) -> 2750 | M7: =G7-K7-L7 -> 3190 | N7: =round(O7*M7+I7,0) -> 0 | O7: 0 | P7: =round(R7*(M7-N7),0) -> 319 | Q7: =round(R7*AD7,0) -> 125 | R7: 0.1 | S7: =round(M7-N7-P7-Q7,0) -> 2746 | T7: =S7/5 -> 549.2 | U7: 600 | V7: =5*(T7-U7) -> -254 | W7: RON | AA7: Backline | AB7: 1000 | AC7: marcel + levi | AD7: 1250 | AK7: Dean | AL7: 500
A8: 29 | B8: Public | C8: Concert Phaser | D8: Flying Circus @ Cluj | G8: 0 | H8: RON | I8: 0 | J8: RON | K8: =round(G8*1%,0) -> 0 | L8: =sum(AB8+AD8+AF8+AH8+AJ8+AL8) -> 750 | M8: =G8-K8-L8 -> -750 | N8: =round(O8*M8+I8,0) -> 0 | O8: 0 | P8: =round(R8*(M8-N8),0) -> 0 | Q8: =round(R8*AD8,0) -> 0 | R8: 0 | S8: =round(M8-N8-P8-Q8,0) -> -750 | T8: =S8/5 -> -150 | U8: 0 | V8: =5*(T8-U8) -> -750 | W8: RON | AA8: Backline | AB8: 0 | AC8: levi | AD8: 750
A9: Martie
A10: 1 | B10: Public | C10: Extra | D10: Radio Tg Mures | G10: 0 | H10: RON | I10: 0 | J10: RON | K10: =round(G10*1%,0) -> 0 | L10: =sum(AB10+AD10+AF10+AH10+AJ10+AL10) -> 750 | M10: =G10-K10-L10 -> -750 | N10: =round(O10*M10+I10,0) -> 0 | O10: 0 | P10: =round(R10*(M10-N10),0) -> 0 | Q10: =round(R10*AD10,0) -> 0 | R10: 0 | S10: =round(M10-N10-P10-Q10,0) -> -750 | T10: =S10/5 -> -150 | U10: 0 | V10: =5*(T10-U10) -> -750 | W10: RON | AA10: Backline | AB10: 0 | AC10: levi | AD10: 750
A11: 1 | B11: Public | C11: Concert Phaser | D11: Republic Hub @ Tg Mures | G11: 880 | H11: RON | I11: 0 | J11: RON | K11: 0 | L11: =sum(AB11+AD11+AF11+AH11+AJ11+AL11) -> 750 | M11: =G11-K11-L11 -> 130 | N11: =round(O11*M11+I11,0) -> 0 | O11: 0 | P11: =round(R11*(M11-N11),0) -> 0 | Q11: =round(R11*AD11,0) -> 0 | R11: 0 | S11: =round(M11-N11-P11-Q11,0) -> 130 | T11: =S11/5 -> 26 | U11: 0 | V11: =5*(T11-U11) -> 130 | W11: RON | AA11: Backline | AB11: 0 | AC11: levi | AD11: 750
A12: 2 | B12: Public | C12: Concert Phaser | D12: NooVo @ Oradea | G12: 1000 | H12: RON | I12: 0 | J12: RON | K12: 0 | L12: =sum(AB12+AD12+AF12+AH12+AJ12+AL12) -> 750 | M12: =G12-K12-L12 -> 250 | N12: =round(O12*M12+I12,0) -> 0 | O12: 0 | P12: =round(R12*(M12-N12),0) -> 0 | Q12: =round(R12*AD12,0) -> 0 | R12: 0 | S12: =round(M12-N12-P12-Q12,0) -> 250 | T12: =S12/5 -> 50 | U12: 0 | V12: =5*(T12-U12) -> 250 | W12: RON | AA12: Backline | AB12: 0 | AC12: levi | AD12: 750
A13: 8 | B13: Public | C13: Concert Phaser | D13: Soho @ Resita | F13: 197 | G13: 7000 | H13: RON | I13: 2000 | J13: RON | K13: =round(G13*1%,0) -> 70 | L13: =sum(AB13+AD13+AF13+AH13+AJ13+AL13) -> 4210 | M13: =G13-K13-L13 -> 2720 | N13: 0 | O13: 0 | P13: =round(R13*(M13-N13),0) -> 0 | Q13: =round(R13*AD13,0) -> 0 | R13: 0 | S13: =round(M13-N13-P13-Q13,0) -> 2720 | T13: =S13/5 -> 544 | U13: 700 | V13: =5*(T13-U13) -> -780 | W13: RON | AA13: Backline | AB13: 1000 | AC13: marcel + levi | AD13: 1250 | AF13: 500 | AG13: protocol | AH13: 260 | AI13: Dean | AJ13: 500 | AK13: comision manger | AL13: 700
A14: Aprilie
A15: 6 | B15: Public | C15: Concert Phaser | D15: Pixel @ Timisoara | G15: 1700 | H15: RON | I15: 0 | J15: RON | K15: 0 | L15: =sum(AB15+AD15+AF15+AH15+AJ15+AL15) -> 3400 | M15: =G15-K15-L15 -> -1700 | N15: =round(O15*M15+I15,0) -> 0 | O15: 0 | P15: =round(R15*(M15-N15),0) -> 0 | Q15: =round(R15*AD15,0) -> 0 | R15: 0 | S15: =round(M15-N15-P15-Q15,0) -> -1700 | T15: =S15/5 -> -340 | U15: 0 | V15: =5*(T15-U15) -> -1700 | W15: RON | AA15: Backline | AB15: 0 | AC15: marcel + levi | AD15: 1000 | AK15: cvartet | AL15: 2400
A16: 7 | B16: Public | C16: Scena Mare | D16: Parcul Padurice | G16: 6000 | H16: RON | I16: 0 | J16: RON | K16: =round(G16*1%,0) -> 60 | L16: =sum(AB16+AD16+AF16+AH16+AJ16+AL16) -> 1500 | M16: =G16-K16-L16 -> 4440 | N16: =round(O16*M16+I16,0) -> 222 | O16: 0.05 | P16: =round(R16*(M16-N16),0) -> 422 | Q16: =round(R16*AD16,0) -> 50 | R16: 0.1 | S16: =round(M16-N16-P16-Q16,0) -> 3746 | T16: =S16/5 -> 749.2 | U16: =round(T16,-1) -> 750 | V16: =5*(T16-U16) -> -4 | W16: RON | AA16: Backline | AB16: 1000 | AC16: levi | AD16: 500
A17: 26 | B17: Public | C17: Concert Phaser | D17: Kai @ Timisoara | G17: 6000 | H17: RON | I17: 0 | J17: RON | K17: =round(G17*1%,0) -> 60 | L17: =sum(AB17+AD17+AF17+AH17+AJ17+AL17) -> 2000 | M17: =G17-K17-L17 -> 3940 | N17: =round(O17*M17+I17,0) -> 0 | O17: 0 | P17: =round(R17*(M17-N17),0) -> 394 | Q17: =round(R17*AD17,0) -> 100 | R17: 0.1 | S17: =round(M17-N17-P17-Q17,0) -> 3446 | T17: =S17/5 -> 689.2 | U17: 700 | V17: =5*(T17-U17) -> -54 | W17: RON | AA17: Backline | AB17: 1000 | AC17: marcel + levi | AD17: 1000
A18: Mai
A19: 12 | B19: Public | C19: Scena Mare | D19: Parcul Bucovina | G19: 6000 | H19: RON | I19: 0 | J19: RON | K19: =round(G19*1%,0) -> 60 | L19: =sum(AB19+AD19+AF19+AH19+AJ19+AL19) -> 2000 | M19: =G19-K19-L19 -> 3940 | N19: =round(O19*M19+I19,0) -> 197 | O19: 0.05 | P19: =round(R19*(M19-N19),0) -> 374 | Q19: =round(R19*AD19,0) -> 100 | R19: 0.1 | S19: =round(M19-N19-P19-Q19,0) -> 3269 | T19: =S19/5 -> 653.8 | U19: =round(T19,-1) -> 650 | V19: =5*(T19-U19) -> 19 | W19: RON | AA19: Backline | AB19: 1000 | AC19: marcel + levi | AD19: 1000
A20: Iunie
A21: 7 | B21: Public | C21: Scena Mare | D21: Centru Civic @ Resita | E21: Aniversare UBB Resita | G21: 4000 | H21: RON | I21: 0 | J21: RON | K21: =round(G21*1%,0) -> 40 | L21: =sum(AB21+AD21+AF21+AH21+AJ21+AL21) -> 2000 | M21: =G21-K21-L21 -> 1960 | N21: =round(O21*M21+I21,0) -> 1960 | O21: 1 | P21: =round(R21*(M21-N21),0) -> 0 | Q21: =round(R21*AD21,0) -> 100 | R21: 0.1 | S21: =round(M21-N21-P21-Q21,0) -> -100 | T21: =S21/5 -> -20 | U21: =round(T21,-1) -> -20 | V21: =5*(T21-U21) -> 0 | W21: RON | AA21: Backline | AB21: 1000 | AC21: marcel + levi | AD21: 1000
A22: 7 | B22: Public | C22: Extra | D22: Radio Resita | E22: Concert in Studio Radio Resita | G22: 0 | H22: RON | I22: 0 | J22: RON | K22: =round(G22*1%,0) -> 0 | L22: =sum(AB22+AD22+AF22+AH22+AJ22+AL22) -> 250 | M22: =G22-K22-L22 -> -250 | N22: =round(O22*M22+I22,0) -> 0 | O22: 0 | P22: =round(R22*(M22-N22),0) -> 0 | Q22: =round(R22*AD22,0) -> 0 | R22: 0 | S22: =round(M22-N22-P22-Q22,0) -> -250 | T22: 0 | U22: 0 | V22: =5*(T22-U22) -> 0 | W22: RON | AA22: Backline | AB22: 0 | AC22: marcel + levi | AD22: 250
A23: 8 | B23: Privat | C23: Nunta | D23: Province | F23: 183 | G23: 3550 | H23: EUR | I23: 300 | J23: EUR | K23: =round(I23*1%,0) -> 3 | L23: =sum(AB23+AD23+AF23+AH23+AJ23+AL23) -> 450 | M23: =G23-K23-L23 -> 3097 | N23: =round(O23*M23+I23,0) -> 579 | O23: 0.09 | P23: =round(R23*(M23-N23),0) -> 0 | Q23: =round(R23*AD23,0) -> 0 | R23: 0 | S23: =round(M23-N23-P23-Q23,0) -> 2518 | T23: =S23/5 -> 503.6 | U23: =round(T23,-1) -> 500 | V23: =5*(T23-U23) -> 18 | W23: EUR | AA23: Backline | AB23: 200 | AD23: 200 | AE23: Buz + Masini | AF23: 50
A24: 9 | B24: Privat | C24: Botez | D24: Province | G24: 21149 | H24: RON | I24: 1492 | J24: RON | K24: =round(G24*1%,0) -> 211 | L24: =sum(AB24+AD24+AF24+AH24+AJ24+AL24) -> 6950 | M24: =G24-K24-L24 -> 13988 | N24: =round(O24*M24+I24,0) -> 2751 | O24: 0.09 | P24: =round(R24*(M24-N24),0) -> 1124 | Q24: =round(R24*AD24,0) -> 100 | R24: 0.1 | S24: =round(M24-N24-P24-Q24,0) -> 10013 | T24: =S24/5 -> 2002.6 | U24: =round(T24,-1) -> 2000 | V24: =5*(T24-U24) -> 13 | W24: RON | AA24: Sunet Full | AB24: 1750 | AD24: 1000 | AE24: Buz + Masini | AF24: 250 | AG24: Flavius | AH24: 1750 | AI24: Flavius | AJ24: 2200
A25: 11 | B25: Privat | C25: Corporate | D25: Serenity @ Codlea | G25: 16920 | H25: RON | I25: 0 | J25: RON | K25: =round(G25*1%,0) -> 169 | L25: =sum(AB25+AD25+AF25+AH25+AJ25+AL25) -> 4750 | M25: =G25-K25-L25 -> 12001 | N25: =round(O25*M25+I25,0) -> 768 | O25: 0.064 | P25: =round(R25*(M25-N25),0) -> 1123 | Q25: =round(R25*AD25,0) -> 125 | R25: 0.1 | S25: =round(M25-N25-P25-Q25,0) -> 9985 | T25: =S25/5 -> 1997 | U25: =round(T25,-1) -> 2000 | V25: =5*(T25-U25) -> -15 | W25: RON | AA25: Backline | AB25: 1000 | AC25: marcel + levi | AD25: 1250 | AE25: Buz + Masini | AF25: 2000 | AL25: 500
A26: 15 | B26: Privat | C26: Nunta | D26: Palatul Brukenthal @ Avrig | G26: 3850 | H26: EUR | I26: 300 | J26: EUR | K26: =round(I26*1%,0) -> 3 | L26: =sum(AB26+AD26+AF26+AH26+AJ26+AL26) -> 570 | M26: =G26-K26-L26 -> 3277 | N26: =round(O26*M26+I26,0) -> 759 | O26: 0.14 | P26: =round(R26*(M26-N26),0) -> 0 | Q26: =round(R26*AD26,0) -> 0 | R26: 0 | S26: =round(M26-N26-P26-Q26,0) -> 2518 | T26: =S26/5 -> 503.6 | U26: =round(T26,-1) -> 500 | V26: =5*(T26-U26) -> 18 | W26: EUR | AA26: Sunet Full | AB26: 350 | AD26: 120 | AE26: Buz + Masini | AF26: 50 | AL26: 50
A27: 21 | B27: Public | C27: Scena Mare | D27: Muzeul Satului | E27: Flight Festival | G27: 7465 | H27: RON | I27: 0 | J27: RON | K27: =round(G27*1%,0) -> 75 | L27: =sum(AB27+AD27+AF27+AH27+AJ27+AL27) -> 1500 | M27: =G27-K27-L27 -> 5890 | N27: =round(O27*M27+I27,0) -> 295 | O27: 0.05 | P27: =round(R27*(M27-N27),0) -> 560 | Q27: =round(R27*AD27,0) -> 50 | R27: 0.1 | S27: =round(M27-N27-P27-Q27,0) -> 4985 | T27: =S27/5 -> 997 | U27: =round(T27,-1) -> 1000 | V27: =5*(T27-U27) -> -15 | W27: RON | AA27: Backline | AB27: 1000 | AD27: 500
A28: 21 | B28: Privat | C28: Nunta | D28: Province | F28: 195 | G28: 4050 | H28: EUR | I28: 300 | J28: EUR | K28: =round(I28*1%,0) -> 3 | L28: =sum(AB28+AD28+AF28+AH28+AJ28+AL28) -> 1100 | M28: =G28-K28-L28 -> 2947 | N28: =round(O28*M28+I28,0) -> 447 | O28: 0.05 | P28: =round(R28*(M28-N28),0) -> 0 | Q28: =round(R28*AD28,0) -> 0 | R28: 0 | S28: =round(M28-N28-P28-Q28,0) -> 2500 | T28: =S28/5 -> 500 | U28: =round(T28,-1) -> 500 | V28: =5*(T28-U28) -> 0 | W28: EUR | AA28: Backline | AB28: 350 | AD28: 200 | AE28: Buz + Masini | AF28: 50 | AG28: Flavius | AH28: 500
A29: 27 | B29: Privat | C29: Corporate | D29: Galla | G29: 12940 | H29: RON | I29: 0 | J29: RON | K29: =round(G29*1%,0) -> 129 | L29: =sum(AB29+AD29+AF29+AH29+AJ29+AL29) -> 2750 | M29: =G29-K29-L29 -> 10061 | N29: =round(O29*M29+I29,0) -> 503 | O29: 0.05 | P29: =round(R29*(M29-N29),0) -> 956 | Q29: =round(R29*AD29,0) -> 100 | R29: 0.1 | S29: =round(M29-N29-P29-Q29,0) -> 8502 | T29: =S29/5 -> 1700.4 | U29: =round(T29,-1) -> 1700 | V29: =5*(T29-U29) -> 2 | W29: RON | AA29: Sunet Full | AB29: 1750 | AD29: 1000
A30: 29 | B30: Privat | C30: Nunta | D30: Province | F30: 184 | G30: 3450 | H30: EUR | I30: 300 | J30: EUR | K30: =round(I30*1%,0) -> 3 | L30: =sum(AB30+AD30+AF30+AH30+AJ30+AL30) -> 450 | M30: =G30-K30-L30 -> 2997 | N30: =round(O30*M30+I30,0) -> 480 | O30: 0.06 | P30: =round(R30*(M30-N30),0) -> 0 | Q30: =round(R30*AD30,0) -> 0 | R30: 0 | S30: =round(M30-N30-P30-Q30,0) -> 2517 | T30: =S30/5 -> 503.4 | U30: =round(T30,-1) -> 500 | V30: =5*(T30-U30) -> 17 | W30: EUR | AA30: Backline | AB30: 200 | AD30: 200 | AE30: Buz + Masini | AF30: 50
A31: Iulie
A32: 5 | B32: Privat | C32: Nunta | D32: Province | F32: 198 | G32: 3600 | H32: EUR | I32: 300 | J32: EUR | K32: =round(I32*1%,0) -> 3 | L32: =sum(AB32+AD32+AF32+AH32+AJ32+AL32) -> 850 | M32: =G32-K32-L32 -> 2747 | N32: =round(O32*M32+I32,0) -> 492 | O32: 0.07 | P32: =round(R32*(M32-N32),0) -> 0 | Q32: =round(R32*AD32,0) -> 0 | R32: 0 | S32: =round(M32-N32-P32-Q32,0) -> 2255 | T32: =S32/5 -> 451 | U32: =round(T32,-1) -> 450 | V32: =5*(T32-U32) -> 5 | W32: EUR | AA32: Backline | AB32: 200 | AD32: 200 | AE32: Buz + Masini | AF32: 50 | AG32: Beni | AH32: 400
A33: 12 | B33: Privat | C33: Nunta | D33: Galla Events | F33: 177 | G33: 2750 | H33: EUR | I33: 300 | J33: EUR | K33: =round(I33*1%,0) -> 3 | L33: =sum(AB33+AD33+AF33+AH33+AJ33+AL33) -> 400 | M33: =G33-K33-L33 -> 2347 | N33: =round(O33*M33+I33,0) -> 323 | O33: 0.01 | P33: =round(R33*(M33-N33),0) -> 0 | Q33: =round(R33*AD33,0) -> 0 | R33: 0 | S33: =round(M33-N33-P33-Q33,0) -> 2024 | T33: =S33/5 -> 404.8 | U33: =round(T33,-1) -> 400 | V33: =5*(T33-U33) -> 24 | W33: EUR | AA33: Backline | AB33: 200 | AD33: 200
A34: 20 | B34: Public | C34: Scena Mare | D34: Deta | E34: Zilele Deta | G34: 7500 | H34: RON | I34: 0 | J34: RON | K34: =round(G34*1%,0) -> 75 | L34: =sum(AB34+AD34+AF34+AH34+AJ34+AL34) -> 2200 | M34: =G34-K34-L34 -> 5225 | N34: =round(O34*M34+I34,0) -> 0 | O34: 0 | P34: =round(R34*(M34-N34),0) -> 523 | Q34: =round(R34*AD34,0) -> 70 | R34: 0.1 | S34: =round(M34-N34-P34-Q34,0) -> 4632 | T34: =S34/5 -> 926.4 | U34: 950 | V34: =5*(T34-U34) -> -118 | W34: RON | AA34: Backline | AB34: 1000 | AD34: 700 | AE34: Buz + Masini | AF34: 500
A35: 25 | B35: Public | C35: Concert Phaser | D35: In spatele Casei | E35: Public/Privat VSU Liceu | G35: 9952 | H35: RON | I35: 0 | J35: RON | K35: =round(G35*1%,0) -> 100 | L35: =sum(AB35+AD35+AF35+AH35+AJ35+AL35) -> 2000 | M35: =G35-K35-L35 -> 7852 | N35: =round(O35*M35+I35,0) -> 236 | O35: 0.03 | P35: =round(R35*(M35-N35),0) -> 762 | Q35: =round(R35*AD35,0) -> 100 | R35: 0.1 | S35: =round(M35-N35-P35-Q35,0) -> 6754 | T35: =S35/5 -> 1350.8 | U35: =round(T35,-1) -> 1350 | V35: =5*(T35-U35) -> 4 | W35: RON | AA35: Backline | AB35: 1000 | AD35: 1000
A36: August
A37: 15 | B37: Public | C37: Scena Mare | D37: Gotlob | E37: Zilele orasului | G37: 9940 | H37: RON | I37: 0 | J37: RON | K37: =round(G37*1%,0) -> 99 | L37: =sum(AB37+AD37+AF37+AH37+AJ37+AL37) -> 3500 | M37: =G37-K37-L37 -> 6341 | N37: =round(O37*M37+I37,0) -> 698 | O37: 0.11 | P37: =round(R37*(M37-N37),0) -> 564 | Q37: =round(R37*AD37,0) -> 100 | R37: 0.1 | S37: =round(M37-N37-P37-Q37,0) -> 4979 | T37: =S37/5 -> 995.8 | U37: =round(T37,-1) -> 1000 | V37: =5*(T37-U37) -> -21 | W37: RON | AA37: Backline | AB37: 1000 | AD37: 1000 | AE37: Buz + Masini | AF37: 500 | AK37: Comision manger | AL37: 1000
A38: 17 | B38: Public | C38: Scena Mare | D38: Dudestii Vechi | E38: Zilele orasului | G38: 9940 | H38: RON | I38: 0 | J38: RON | K38: =round(G38*1%,0) -> 99 | L38: =sum(AB38+AD38+AF38+AH38+AJ38+AL38) -> 2500 | M38: =G38-K38-L38 -> 7341 | N38: =round(O38*M38+I38,0) -> 587 | O38: 0.08 | P38: =round(R38*(M38-N38),0) -> 675 | Q38: =round(R38*AD38,0) -> 100 | R38: 0.1 | S38: =round(M38-N38-P38-Q38,0) -> 5979 | T38: =S38/5 -> 1195.8 | U38: =round(T38,-1) -> 1200 | V38: =5*(T38-U38) -> -21 | W38: RON | AA38: Backline | AB38: 1000 | AD38: 1000 | AE38: Buz + Masini | AF38: 500
A39: 25 | B39: Privat | C39: Nunta | D39: Venue | G39: 12434 | H39: RON | I39: 0 | J39: RON | K39: =round(G39*1%,0) -> 124 | L39: =sum(AB39+AD39+AF39+AH39+AJ39+AL39) -> 2000 | M39: =G39-K39-L39 -> 10310 | N39: =round(O39*M39+I39,0) -> 464 | O39: 0.045 | P39: =round(R39*(M39-N39),0) -> 985 | Q39: =round(R39*AD39,0) -> 100 | R39: 0.1 | S39: =round(M39-N39-P39-Q39,0) -> 8761 | T39: =S39/5 -> 1752.2 | U39: =round(T39,-1) -> 1750 | V39: =5*(T39-U39) -> 11 | W39: RON | AA39: Backline | AB39: 1000 | AD39: 1000
A40: 30 | B40: Public | C40: Scena Mare | D40: Centru Civic @ Resita | E40: Aniversare Banatul Montan | G40: 8700 | H40: RON | I40: 0 | J40: RON | K40: =round(G40*1%,0) -> 87 | L40: =sum(AB40+AD40+AF40+AH40+AJ40+AL40) -> 2500 | M40: =G40-K40-L40 -> 6113 | N40: =round(O40*M40+I40,0) -> 428 | O40: 0.07 | P40: =round(R40*(M40-N40),0) -> 569 | Q40: =round(R40*AD40,0) -> 100 | R40: 0.1 | S40: =round(M40-N40-P40-Q40,0) -> 5016 | T40: =S40/5 -> 1003.2 | U40: =round(T40,-1) -> 1000 | V40: =5*(T40-U40) -> 16 | W40: RON | AA40: Backline | AB40: 1000 | AD40: 1000 | AF40: 500
...

Sheet Onorariu Artist 2024
F1: Onorariu Artist
A2: Data | B2: Tip Event | C2: Specific | D2: Locatie | E2: Descriere | F2: POSIBIL | G2: REAL | H2: Valuta | I2: Carina | J2: Arni | K2: Radu | L2: Sebi | M2: Luci
A3: Ianuarie
A4: 27 | B4: Privat | C4: Nunta | D4: Flonta (Lakeside) | F4: 530 | G4: 500 | H4: EUR | I4: 500 | J4: 500 | K4: 500 | L4: 500 | M4: 500
A5: 29 | B5: Public | C5: Extra | D5: Radio Resita | E5: Concert in Studio Radio Resita | F5: 0 | G5: 0 | H5: RON | I5: 0 | J5: 0 | K5: 0 | L5: 0 | M5: 0
A6: Februarie
A7: 2 | B7: Public | C7: Concert Phaser | D7: Kai @ Timisoara | F7: 550 | G7: 600 | H7: RON | I7: 600 | J7: 600 | K7: 600 | L7: 600 | M7: 600
A8: 29 | B8: Public | C8: Concert Phaser | D8: Flying Circus @ Cluj | F8: 0 | G8: 0 | H8: RON | I8: 0 | J8: 0 | K8: 0 | L8: 0 | M8: 0
A9: Martie
A10: 1 | B10: Public | C10: Extra | D10: Radio Tg Mures | F10: 0 | G10: 0 | H10: RON | I10: 0 | J10: 0 | K10: 0 | L10: 0 | M10: 0
A11: 1 | B11: Public | C11: Concert Phaser | D11: Republic Hub @ Tg Mures | F11: 0 | G11: 0 | H11: RON | I11: 0 | J11: 0 | K11: 0 | L11: 0 | M11: 0
A12: 2 | B12: Public | C12: Concert Phaser | D12: NooVo @ Oradea | F12: 0 | G12: 0 | H12: RON | I12: 0 | J12: 0 | K12: 0 | L12: 0 | M12: 0
A13: 8 | B13: Public | C13: Concert Phaser | D13: Soho @ Resita | F13: 550 | G13: 700 | H13: RON | I13: 700 | J13: 700 | K13: 700 | L13: 700 | M13: 700
A14: Aprilie
A15: 6 | B15: Public | C15: Concert Phaser | D15: Pixel @ Timisoara | F15: 0 | G15: 0 | H15: RON | I15: 0 | J15: 0 | K15: 0 | L15: 0 | M15: 0
A16: 7 | B16: Public | C16: Scena Mare | D16: Parcul Padurice | F16: 790 | G16: 750 | H16: RON | I16: 750 | J16: 750 | K16: 750 | L16: 750 | M16: 750
A17: 26 | B17: Public | C17: Concert Phaser | D17: Kai @ Timisoara | F17: 690 | G17: 700 | H17: RON | I17: 700 | J17: 700 | K17: 700 | L17: 700 | M17: 700
A18: Mai
A19: 12 | B19: Public | C19: Scena Mare | D19: Parcul Bucovina | F19: 690 | G19: 650 | H19: RON | I19: 650 | J19: 650 | K19: 650 | L19: 650 | M19: 650
A20: Iunie
A21: 7 | B21: Public | C21: Scena Mare | D21: Centru Civic @ Resita | E21: Aniversare UBB Resita | F21: 330 | G21: 0 | H21: RON | I21: 0 | J21: 0 | K21: 0 | L21: 0 | M21: 0
A22: 7 | B22: Public | C22: Extra | D22: Radio Resita | E22: Concert in Studio Radio Resita | F22: 0 | G22: 0 | H22: RON | I22: 0 | J22: 0 | K22: 0 | L22: 0 | M22: 0
A23: 8 | B23: Privat | C23: Nunta | D23: Province | F23: 560 | G23: 500 | H23: EUR | I23: 500 | J23: 500 | K23: 500 | L23: 500 | M23: 500
A24: 9 | B24: Privat | C24: Botez | D24: Province | F24: 2230 | G24: 2000 | H24: RON | I24: 2000 | J24: 2000 | K24: 2000 | L24: 2000 | M24: 2000
A25: 11 | B25: Privat | C25: Corporate | D25: Serenity @ Codlea | F25: 2140 | G25: 2000 | H25: RON | I25: 2000 | J25: 2000 | K25: 2000 | L25: 2000 | M25: 2000
A26: 15 | B26: Privat | C26: Nunta | D26: Palatul Brukental @ Avrig | F26: 500 | G26: 500 | H26: EUR | I26: 500 | J26: 500 | K26: 500 | L26: 500 | M26: 500
A27: 21 | B27: Public | C27: Scena Mare | D27: Muzeul Satului | F27: 1050 | G27: 1000 | H27: RON | I27: 1000 | J27: 1000 | K27: 1000 | L27: 1000 | M27: 1000
A28: 21 | B28: Privat | C28: Nunta | D28: Province | F28: 530 | G28: 500 | H28: EUR | I28: 500 | J28: 500 | K28: 500 | L28: 500 | M28: 500
A29: 27 | B29: Privat | C29: Corporate | D29: Galla | F29: 1790 | G29: 1700 | H29: RON | I29: 1700 | J29: 1700 | K29: 1700 | L29: 1700 | M29: 1700
A30: 29 | B30: Privat | C30: Nunta | D30: Province | F30: 540 | G30: 500 | H30: EUR | I30: 500 | J30: 500 | K30: 500 | L30: 500 | M30: 500
A31: Iulie
A32: 5 | B32: Privat | C32: Nunta | D32: Province | F32: 480 | G32: 450 | H32: EUR | I32: 450 | J32: 450 | K32: 450 | L32: 450 | M32: 450
A33: 12 | B33: Privat | C33: Nunta | D33: Galla Events | F33: 400 | G33: 400 | H33: EUR | I33: 400 | J33: 400 | K33: 400 | L33: 400 | M33: 400
A34: 20 | B34: Public | C34: Scena Mare | D34: Deta | E34: =AVERAGE(G44:G51) -> 992.85714 | F34: 950 | G34: 950 | H34: RON | I34: 950 | J34: 950 | K34: 950 | L34: 950 | M34: 950
A35: 25 | B35: Public | C35: Concert Phaser | D35: In spatele Casei | E35: Public/Privat VSU Liceu | F35: 1390 | G35: 1350 | H35: RON | I35: 1350 | J35: 1350 | K35: 1350 | L35: 1350 | M35: 1350
A36: August
A37: 15 | B37: Public | C37: Scena Mare | D37: Gotlob | E37: Zilele orasului | F37: 1120 | G37: 1000 | H37: RON | I37: 1000 | J37: 1000 | K37: 1000 | L37: 1000 | M37: 1000
A38: 17 | B38: Public | C38: Scena Mare | D38: Dudestii Vechi | E38: Zilele orasului | F38: 1300 | G38: 1200 | H38: RON | I38: 1200 | J38: 1200 | K38: 1200 | L38: 1200 | M38: 1200
A39: 25 | B39: Privat | C39: Nunta | D39: Venue | F39: 1840 | G39: 1750 | H39: RON | I39: 1750 | J39: 1750 | K39: 1750 | L39: 1750 | M39: 1750
A40: 30 | B40: Public | C40: Scena Mare | D40: Centru Civic @ Resita | E40: Aniversare Banatul Montan | F40: 1080 | G40: 1000 | H40: RON | I40: 1000 | J40: 1000 | K40: 1000 | L40: 1000 | M40: 1000
...

Sheet Tranzactii 2024
B1: Cheltuieli | G1: Venituri | L1: Retrageri | N1: Depuneri
A2: Data | B2: Suma | C2: Valuta | D2: Categorie | E2: Descriere | F2: Mod | G2: Suma | H2: Valuta | I2: Categorie | J2: Descriere | K2: Mod | L2: Suma | M2: Descriere | N2: Suma | O2: Descriere
A3: 44927 | C3: Ron | G3: 626.46 | H3: Ron | J3: Sold initial 2024 | K3: Cash
G4: 40044.54 | H4: Ron | J4: Sold initial 2024 | K4: Banca
A8: 45293 | B8: 99.99 | C8: Ron | D8: Drive | F8: Banca
B9: 1244.81 | C9: Ron | D9: Promo Meta | F9: Banca
B10: 6750 | C10: Ron | D10: Prezent | F10: Banca
B11: 0.45 | C11: Ron | D11: Comision Operatiune | F11: Banca
A12: 45294 | B12: 160.64 | C12: Ron | D12: Drive | F12: Banca
A13: 45296 | L13: 5000
A14: 45300 | G14: 1491 | H14: Ron | I14: Avans | J14: party aprilie 2024 | K14: Banca
A15: 45302 | B15: 285.48 | C15: Ron | D15: Factureaza | F15: Banca
A16: 45307 | B16: 500 | C16: Ron | D16: Drum | E16: recuperari province 2023 | F16: Cash
A17: 45313 | B17: 3500 | C17: Ron | D17: Sala CS | E17: din 2023 restanta + 2024 full | F17: Cash | L17: 2500
B18: 8.75 | C18: Ron | D18: Comision Retrageri | F18: Banca
A19: 45314 | B19: 5 | C19: Ron | D19: Comision Retrageri | F19: Banca | G19: 5000 | H19: Ron | I19: Event | J19: ccs resita dec 2023 | K19: Banca | L19: 500
B20: 2.5 | C20: Ron | D20: Comision Retrageri | F20: Banca
A21: 45316 | B21: 3912 | C21: Ron | D21: Salariu | F21: Banca
B22: 222 | C22: Ron | D22: Salariu | F22: Banca
B23: 304 | C23: Ron | D23: TVA | F23: Banca
A24: 45319 | B24: 500 | C24: Euro | D24: Sebi | E24: event 27.01.2024 | F24: Cash | G24: 3000 | H24: Euro | I24: Event | J24: event 27.01.2024 | K24: Cash
B25: 500 | C25: Euro | D25: Luci | E25: event 27.01.2024 | F25: Cash
B26: 500 | C26: Euro | D26: Arni | E26: event 27.01.2024 | F26: Cash
B27: 500 | C27: Euro | D27: Radu | E27: event 27.01.2024 | F27: Cash
B28: 500 | C28: Euro | D28: Carina | E28: event 27.01.2024 | F28: Cash
B29: 350 | C29: Euro | D29: Prezent | E29: event 27.01.2024 | F29: Cash
B30: 100 | C30: Euro | D30: Altele | F30: Cash
A31: 45320 | B31: 250 | C31: Ron | D31: Tehnici | F31: Cash
A32: 45322 | L32: 10000
A35: 45323 | B35: 11350 | C35: Ron | D35: Sebi | E35: restul de cantari pe 2023 | F35: Cash | L35: 2500
B36: 300 | C36: Ron | D36: Drum | E36: arni drum recuperari 2023 | F36: Cash
B37: 300 | C37: Ron | D37: Drum | E37: carina drum recuperari 2023 + radio resita 2024 | F37: Cash
B38: 200 | C38: Ron | D38: Drum | E38: radu drum radio resita 2024 | F38: Cash
B39: 300 | C39: Ron | D39: Drum | E39: arni drum recuperari 2023 | F39: Cash
B40: 3350 | C40: Ron | D40: Luci | E40: restul de cantari 2022 | F40: Cash
B41: 700 | C41: Ron | D41: Drum | E41: luci drum 2023 + radio resita | F41: Cash
A42: 45324 | B42: 54 | C42: Ron | D42: Altele | E42: cartela telefon pentru nunti | F42: Cash | L42: 1500
A43: 45325 | B43: 500 | C43: Ron | D43: Tehnici | E43: kai event marci | F43: Cash | L43: 2000
B44: 750 | C44: Ron | D44: Tehnici | E44: kai event levi + sunet | F44: Cash
B45: 500 | C45: Ron | D45: Altele | E45: dean kai event | F45: Cash
...

Sheet DatoriiRecuperari 2024
A1: TOTAL DATORII | C1: Datorie Prezent | G1: Datorii persoane | K1: Alte datorii | N1: Recuperari
A2: =A5+A8+A11 -> 0
A4: Total Prezent
A5: =sum(E:E) -> 0
A7: Total Pesoane
A8: =sum(I:I) -> 0
A10: Total alte datorii
A11: =sum(L:L) -> 0
A13: TOTAL RECUPERARI
A14: =sum(P:P) -> 0

Sheet Situatie 2023
A1: Venituri RON | B1: =SUMIF('Tranzactii 2023'!H:H,'Tranzactii 2023'!H3,'Tranzactii 2023'!G:G)-'Tranzactii 2023'!G4+'Tranzactii 2023'!G3 -> 291910 | E1: Restul RON | F1: =sumif('Evenimente 2023'!W:W,'Evenimente 2023'!W14,'Evenimente 2023'!V:V) -> -677 | H1: Total Events | I1: =COUNT('Evenimente 2023'!A:A) -> 47 | L1: Eur | M1: 4.9
A2: Venituri EUR | B2: =sumif('Tranzactii 2023'!H:H,'Tranzactii 2023'!H100,'Tranzactii 2023'!G:G) -> 39700 | E2: Restul EUR | F2: =sumif('Evenimente 2023'!W:W,'Evenimente 2023'!W12,'Evenimente 2023'!V:V) -> -52
A3: Cheltuieli RON | B3: =SUMIF('Tranzactii 2023'!C:C,'Tranzactii 2023'!C3,'Tranzactii 2023'!B:B) -> 297822.55 | E3: Total Restul | F3: =round(F2+F1/M1,0) -> -190 | H3: Public | I3: =countif('Evenimente 2023'!B:B,H3) -> 22
A4: Cheltuieli EUR | B4: =sumif('Tranzactii 2023'!C:C,'Tranzactii 2023'!C101,'Tranzactii 2023'!B:B) -> 39700 | H4: Concert Phaser | I4: =COUNTIF('Evenimente 2023'!C:C,H4) -> 9
A5: Retrageri | B5: =sum('Tranzactii 2023'!L:L) -> 148090 | C5: ron | E5: Fond RON | F5: =sumif('Evenimente 2023'!W:W,'Evenimente 2023'!W5,'Evenimente 2023'!N:N) -> 54380 | H5: Scena mare | I5: =COUNTIF('Evenimente 2023'!C:C,H5) -> 13
